Workbook
Name Праздники: OFFSET(Праздники!$A$1,0,0,COUNTA(Праздники!$A$1:$A$21),1)

Sheet TaskList
C1: Календарный график проекта
C3: Дата начала проекта | E3: 46113 | F3: FALSE
C4: Дата окончания проекта | E4: 46296 | I4: Responsible - ответственный исполнитель | J4: Accountable - владелец результата (приемка задачи) | K4: Consulted - консультант/ эксперт | L4: Informed - Информируемый
C5: Шаг временной шкалы (дней/клетку) | E5: 1
J7: Accountable - владелец результата (приемка задачи) | K7: Consulted - консультант/ эксперт | L7: Informed - Информируемый | P7: =IF(P8=TODAY(),CHAR(113),"") | Q7: =IF(Q8=TODAY(),CHAR(113),"") | R7: =IF(R8=TODAY(),CHAR(113),"") | S7: =IF(S8=TODAY(),CHAR(113),"") | T7: =IF(T8=TODAY(),CHAR(113),"") | U7: =IF(U8=TODAY(),CHAR(113),"") | V7: =IF(V8=TODAY(),CHAR(113),"") | W7: =IF(W8=TODAY(),CHAR(113),"") | ... EX7: =IF(EX8=TODAY(),CHAR(113),"")
B8: № | C8: Этап | D8: Ответственный | E8: Начало этапа | F8: =IF(F3,"Длительность, раб.дн.","Длительность, дн.") -> Длительность, дн. | G8: Конец этапа | H8: % выполнения | I8: R | J8: A | K8: C | L8: I | M8: Подтверждение результата | N8: Nex steps | O8: Комментарий | P8: =E3 -> 46113 | Q8: =IF(P8<=$E$4,P8+$E$5,"") -> 46114 | R8: =IF(Q8<=$E$4,Q8+$E$5,"") -> 46115 | S8: =IF(R8<=$E$4,R8+$E$5,"") -> 46116 | T8: =IF(S8<=$E$4,S8+$E$5,"") -> 46117 | U8: =IF(T8<=$E$4,T8+$E$5,"") -> 46118 | V8: =IF(U8<=$E$4,U8+$E$5,"") -> 46119 | W8: =IF(V8<=$E$4,V8+$E$5,"") -> 46120 | X8: =IF(W8<=$E$4,W8+$E$5,"") -> 46121 | ... IR8: =IF(IQ8<=$E$4,IQ8+$E$5,"")
B9: 1. Бизнес-анализ и описание требований | E9: 46113 | F9: =NETWORKDAYS(E9,G9,Праздники!$A$1:$A$14) -> 27 | G9: 46150 | H9: =AVERAGE(H10:H26) -> 0.79642857 | P9: =IF(P$8=TODAY(),CHAR(124),"") | Q9: =IF(Q$8=TODAY(),CHAR(124),"") | R9: =IF(R$8=TODAY(),CHAR(124),"") | S9: =IF(S$8=TODAY(),CHAR(124),"") | T9: =IF(T$8=TODAY(),CHAR(124),"") | U9: =IF(U$8=TODAY(),CHAR(124),"") | V9: =IF(V$8=TODAY(),CHAR(124),"") | W9: =IF(W$8=TODAY(),CHAR(124),"") | ... EX9: =IF(EX$8=TODAY(),CHAR(124),"")
B10: 1.1 | C10: Описание бизнес-процессов в части HC Tracker и HCMC forms | D10: А. Колесов | E10: 46113 | F10: =NETWORKDAYS(E10,G10,Праздники!$A$1:$A$14) -> 22 | G10: 46142 | H10: 1 | I10: AKol | J10: VD | K10: EA, YuR | L10: EA, YuR, Akor | M10: Бизнес-анализ HC Tracker и HCMC.docx | P10: =IF(P$8=TODAY(),CHAR(124),"") | Q10: =IF(Q$8=TODAY(),CHAR(124),"") | R10: =IF(R$8=TODAY(),CHAR(124),"") | S10: =IF(S$8=TODAY(),CHAR(124),"") | T10: =IF(T$8=TODAY(),CHAR(124),"") | U10: =IF(U$8=TODAY(),CHAR(124),"") | V10: =IF(V$8=TODAY(),CHAR(124),"") | W10: =IF(W$8=TODAY(),CHAR(124),"") | ... EX10: =IF(EX$8=TODAY(),CHAR(124),"")
B11: 1.2 | C11: Анализ HCMC форм | D11: А. Коршунов | E11: 46141 | F11: =NETWORKDAYS(E11,G11,Праздники!$A$1:$A$14) -> 5 | G11: 46148 | H11: 1 | I11: AKor | P11: =IF(P$8=TODAY(),CHAR(124),"") | Q11: =IF(Q$8=TODAY(),CHAR(124),"") | R11: =IF(R$8=TODAY(),CHAR(124),"") | S11: =IF(S$8=TODAY(),CHAR(124),"") | T11: =IF(T$8=TODAY(),CHAR(124),"") | U11: =IF(U$8=TODAY(),CHAR(124),"") | V11: =IF(V$8=TODAY(),CHAR(124),"") | W11: =IF(W$8=TODAY(),CHAR(124),"") | ... EX11: =IF(EX$8=TODAY(),CHAR(124),"")
B12: 1.3 | C12: Альбом/описание бюджетных форм | D12: Лена, Юра, Женя | E12: 46133 | F12: =NETWORKDAYS(E12,G12,Праздники!$A$1:$A$14) -> 6 | G12: 46140 | H12: 1 | I12: EE, YuR | K12: EA | L12: EA | P12: =IF(P$8=TODAY(),CHAR(124),"") | Q12: =IF(Q$8=TODAY(),CHAR(124),"") | R12: =IF(R$8=TODAY(),CHAR(124),"") | S12: =IF(S$8=TODAY(),CHAR(124),"") | T12: =IF(T$8=TODAY(),CHAR(124),"") | U12: =IF(U$8=TODAY(),CHAR(124),"") | V12: =IF(V$8=TODAY(),CHAR(124),"") | W12: =IF(W$8=TODAY(),CHAR(124),"") | ... EX12: =IF(EX$8=TODAY(),CHAR(124),"")
B13: 1.3.1 | C13: Аудит и актуализация альбома бюджетных форм - Кроме Банка | E13: 46269 | F13: =NETWORKDAYS(E13,G13,Праздники!$A$1:$A$14) -> 6 | G13: 46276 | H13: 0.1 | I13: YuR, AO, EE | J13: YuR, EE | K13: EA
B14: 1.3.1 | C14: Аудит и актуализация альбома бюджетных форм - Банковская | E14: 46269 | F14: =NETWORKDAYS(E14,G14,Праздники!$A$1:$A$14) -> 6 | G14: 46276 | H14: 1 | I14: EE | J14: EE | K14: EA | L14: AO, YuR | N14: прислать ссылку на формы
B15: 1.4 | C15: Альбом/описание отчетных форм | D15: Лена, Юра, Женя | E15: 46133 | F15: =NETWORKDAYS(E15,G15,Праздники!$A$1:$A$14) -> 6 | G15: 46140 | H15: 1 | I15: EE, YuR | J15: DZh | K15: EA | L15: Ea, SO | P15: =IF(P$8=TODAY(),CHAR(124),"") | Q15: =IF(Q$8=TODAY(),CHAR(124),"") | R15: =IF(R$8=TODAY(),CHAR(124),"") | S15: =IF(S$8=TODAY(),CHAR(124),"") | T15: =IF(T$8=TODAY(),CHAR(124),"") | U15: =IF(U$8=TODAY(),CHAR(124),"") | V15: =IF(V$8=TODAY(),CHAR(124),"") | W15: =IF(W$8=TODAY(),CHAR(124),"") | ... EX15: =IF(EX$8=TODAY(),CHAR(124),"")
B16: 1.4.1 | C16: Аудит и актуализация альбома отчетных форм - Кроме Банка | E16: 46269 | F16: =NETWORKDAYS(E16,G16,Праздники!$A$1:$A$14) -> 6 | G16: 46276 | H16: 0.1 | I16: YuR, AO, EE | J16: YuR, EE | K16: EA
B17: 1.4.1.1 | C17: Форма 1.1_план-факт ФОТ | D17: Лена, Юра, Женя | E17: 46133 | F17: =NETWORKDAYS(E17,G17,Праздники!$A$1:$A$14) -> 6 | G17: 46140 | H17: 1 | I17: YuR | J17: DZh | K17: EE, AO, EA, VD | L17: EE, AO, EA, VD | M17: Форма 1_План-факт ФОТ
B18: 1.4.1.2 | C18: Форма 1.2_Waterfall по факторному анализу
B19: 1.4.1.3 | C19: Форма 3
B20: 1.4.1.4 | C20: Форма 4 и тд
B21: 1.4.1.5 | C21: Набор отчетных форм по HC Tracker | E21: 46133 | F21: =NETWORKDAYS(E21,G21,Праздники!$A$1:$A$14) -> 6 | G21: 46140 | H21: 1 | I21: YuR | J21: YuR | L21: HR Advisory
B22: 1.4.2 | C22: Аудит и актуализация альбома отчетных форм - Банковская | E22: 46269 | F22: =NETWORKDAYS(E22,G22,Праздники!$A$1:$A$14) -> 6 | G22: 46276 | H22: 1 | I22: EE | J22: EE | K22: EA | L22: AO, YuR
B23: 5 | C23: Детальное описание форм | D23: Аня | E23: 46189 | F23: =NETWORKDAYS(E23,G23,Праздники!$A$1:$A$14) -> 64 | G23: 46276 | H23: 0.5 | I23: AO | K23: EE, YuR, EA | O23: Описание методологии подготовки бюджетных и отчетных форм (в т.ч. Accruals и тд)
B24: 6 | C24: Описание/макеты Бюджетных/Comp Dashboards | D24: Лена, Юра, Женя | E24: 46154 | F24: =NETWORKDAYS(E24,G24,Праздники!$A$1:$A$14) -> 100 | G24: 46294 | H24: 0.5 | I24: EE, YuR, EA, AO | J24: DZh | N24: Провести встречу по оценке возможностей реализации дашбордов - приоритеты и сроки
B25: 7 | C25: Разработка пользовательских сценариев для HC Tracker и HCMC forms | D25: А. Колесов | E25: 46146 | F25: =NETWORKDAYS(E25,G25,Праздники!$A$1:$A$14) -> 9 | G25: 46158 | H25: 1 | I25: AKol | J25: VD, AO | L25: VD, AO, YuR | M25: Пользовательские сценарии.docx | P25: =IF(P$8=TODAY(),CHAR(124),"") | Q25: =IF(Q$8=TODAY(),CHAR(124),"") | R25: =IF(R$8=TODAY(),CHAR(124),"") | S25: =IF(S$8=TODAY(),CHAR(124),"") | T25: =IF(T$8=TODAY(),CHAR(124),"") | U25: =IF(U$8=TODAY(),CHAR(124),"") | V25: =IF(V$8=TODAY(),CHAR(124),"") | W25: =IF(W$8=TODAY(),CHAR(124),"") | ... EX25: =IF(EX$8=TODAY(),CHAR(124),"")
B26: =B25+1 -> 8 | C26: Мэппинг статей затрат | D26: Юра, Лена | E26: 46146 | F26: =NETWORKDAYS(E26,G26,Праздники!$A$1:$A$14) -> 93 | G26: 46276 | H26: 0.95 | I26: YuR | J26: YuR | K26: VD | M26: Реализация в 1С в разделе "Учет ЦБ" -> Мэппинг счетов МСФО | P26: =IF(P$8=TODAY(),CHAR(124),"") | Q26: =IF(Q$8=TODAY(),CHAR(124),"") | R26: =IF(R$8=TODAY(),CHAR(124),"") | S26: =IF(S$8=TODAY(),CHAR(124),"") | T26: =IF(T$8=TODAY(),CHAR(124),"") | U26: =IF(U$8=TODAY(),CHAR(124),"") | V26: =IF(V$8=TODAY(),CHAR(124),"") | W26: =IF(W$8=TODAY(),CHAR(124),"") | ... EX26: =IF(EX$8=TODAY(),CHAR(124),"")
B27: результат | C27: Описаны бизнес-процессы, формы, пользовательские сценарии | D27: Вася | E27: 46150 | F27: =NETWORKDAYS(E27,G27,Праздники!$A$1:$A$14) -> 1 | G27: 46150 | H27: 1 | I27: VD | P27: =IF(P$8=TODAY(),CHAR(124),"") | Q27: =IF(Q$8=TODAY(),CHAR(124),"") | R27: =IF(R$8=TODAY(),CHAR(124),"") | S27: =IF(S$8=TODAY(),CHAR(124),"") | T27: =IF(T$8=TODAY(),CHAR(124),"") | U27: =IF(U$8=TODAY(),CHAR(124),"") | V27: =IF(V$8=TODAY(),CHAR(124),"") | W27: =IF(W$8=TODAY(),CHAR(124),"") | ... EX27: =IF(EX$8=TODAY(),CHAR(124),"")
B28: 2. Проектирование | E28: 46132 | F28: =NETWORKDAYS(E28,G28,Праздники!$A$1:$A$14) -> 18 | G28: 46157 | P28: =IF(P$8=TODAY(),CHAR(124),"") | Q28: =IF(Q$8=TODAY(),CHAR(124),"") | R28: =IF(R$8=TODAY(),CHAR(124),"") | S28: =IF(S$8=TODAY(),CHAR(124),"") | T28: =IF(T$8=TODAY(),CHAR(124),"") | U28: =IF(U$8=TODAY(),CHAR(124),"") | V28: =IF(V$8=TODAY(),CHAR(124),"") | W28: =IF(W$8=TODAY(),CHAR(124),"") | ... EX28: =IF(EX$8=TODAY(),CHAR(124),"")
B29: 2.1. | C29: Разработка архитектуры решения | D29: Вася | E29: 46139 | F29: =NETWORKDAYS(E29,G29,Праздники!$A$1:$A$14) -> 6 | G29: 46147 | H29: 1 | I29: VD | P29: =IF(P$8=TODAY(),CHAR(124),"") | Q29: =IF(Q$8=TODAY(),CHAR(124),"") | R29: =IF(R$8=TODAY(),CHAR(124),"") | S29: =IF(S$8=TODAY(),CHAR(124),"") | T29: =IF(T$8=TODAY(),CHAR(124),"") | U29: =IF(U$8=TODAY(),CHAR(124),"") | V29: =IF(V$8=TODAY(),CHAR(124),"") | W29: =IF(W$8=TODAY(),CHAR(124),"") | ... EX29: =IF(EX$8=TODAY(),CHAR(124),"")
B30: 2.2. | C30: Разработка моделей данных | E30: 46132 | F30: =NETWORKDAYS(E30,G30,Праздники!$A$1:$A$14) -> 104 | G30: =MAX(G31:G35) -> 46280 | H30: =AVERAGE(H31:H35) -> 0.74 | P30: =IF(P$8=TODAY(),CHAR(124),"") | Q30: =IF(Q$8=TODAY(),CHAR(124),"") | R30: =IF(R$8=TODAY(),CHAR(124),"") | S30: =IF(S$8=TODAY(),CHAR(124),"") | T30: =IF(T$8=TODAY(),CHAR(124),"") | U30: =IF(U$8=TODAY(),CHAR(124),"") | V30: =IF(V$8=TODAY(),CHAR(124),"") | W30: =IF(W$8=TODAY(),CHAR(124),"") | ... EX30: =IF(EX$8=TODAY(),CHAR(124),"")
B31: 2.2.1. | C31: HC трекер | D31: Женя | E31: 46132 | F31: =NETWORKDAYS(E31,G31,Праздники!$A$1:$A$14) -> 14 | G31: 46150 | H31: 1 | I31: EA | J31: VD | M31: HC_TRACKER_ER_Diagramm | P31: =IF(P$8=TODAY(),CHAR(124),"") | Q31: =IF(Q$8=TODAY(),CHAR(124),"") | R31: =IF(R$8=TODAY(),CHAR(124),"") | S31: =IF(S$8=TODAY(),CHAR(124),"") | T31: =IF(T$8=TODAY(),CHAR(124),"") | U31: =IF(U$8=TODAY(),CHAR(124),"") | V31: =IF(V$8=TODAY(),CHAR(124),"") | W31: =IF(W$8=TODAY(),CHAR(124),"") | ... EX31: =IF(EX$8=TODAY(),CHAR(124),"")
B32: 2.2.1. | C32: HC трекер - доработки после тестирования | E32: 46258 | F32: =NETWORKDAYS(E32,G32,Праздники!$A$1:$A$14) -> 10 | G32: 46269 | H32: 0.3 | I32: EA | J32: VD | N32: Last changes Update
B33: 2.2.2. | C33: HCMC | D33: Вася, А. Коршунов | E33: 46149 | F33: =NETWORKDAYS(E33,G33,Праздники!$A$1:$A$14) -> 2 | G33: 46150 | H33: 1 | I33: VD, AKor | P33: =IF(P$8=TODAY(),CHAR(124),"") | Q33: =IF(Q$8=TODAY(),CHAR(124),"") | R33: =IF(R$8=TODAY(),CHAR(124),"") | S33: =IF(S$8=TODAY(),CHAR(124),"") | T33: =IF(T$8=TODAY(),CHAR(124),"") | U33: =IF(U$8=TODAY(),CHAR(124),"") | V33: =IF(V$8=TODAY(),CHAR(124),"") | W33: =IF(W$8=TODAY(),CHAR(124),"") | ... EX33: =IF(EX$8=TODAY(),CHAR(124),"")
B34: 2.2.3. | C34: Бюджетная система | D34: Женя | E34: 46149 | F34: =NETWORKDAYS(E34,G34,Праздники!$A$1:$A$14) -> 2 | G34: 46150 | H34: 1 | I34: EA | J34: VD | M34: Budgt system ER diagram | P34: =IF(P$8=TODAY(),CHAR(124),"") | Q34: =IF(Q$8=TODAY(),CHAR(124),"") | R34: =IF(R$8=TODAY(),CHAR(124),"") | S34: =IF(S$8=TODAY(),CHAR(124),"") | T34: =IF(T$8=TODAY(),CHAR(124),"") | U34: =IF(U$8=TODAY(),CHAR(124),"") | V34: =IF(V$8=TODAY(),CHAR(124),"") | W34: =IF(W$8=TODAY(),CHAR(124),"") | ... EX34: =IF(EX$8=TODAY(),CHAR(124),"")
B35: 2.2.3.1 | C35: Бюджетная система - доработки после тестирования | E35: 46204 | F35: =NETWORKDAYS(E35,G35,Праздники!$A$1:$A$14) -> 55 | G35: 46280 | H35: 0.4 | I35: EA | J35: VD | N35: Last changes Update
B36: 2.3. | C36: Описание цепочек обработки данных | D36: А. Колесов | E36: 46147 | F36: =NETWORKDAYS(E36,G36,Праздники!$A$1:$A$14) -> 4 | G36: 46150 | H36: 1 | I36: Akol | J36: VD | M36: Общий процесс HC Tracker\sequence hc tracker v4.docx | P36: =IF(P$8=TODAY(),CHAR(124),"") | Q36: =IF(Q$8=TODAY(),CHAR(124),"") | R36: =IF(R$8=TODAY(),CHAR(124),"") | S36: =IF(S$8=TODAY(),CHAR(124),"") | T36: =IF(T$8=TODAY(),CHAR(124),"") | U36: =IF(U$8=TODAY(),CHAR(124),"") | V36: =IF(V$8=TODAY(),CHAR(124),"") | W36: =IF(W$8=TODAY(),CHAR(124),"") | ... EX36: =IF(EX$8=TODAY(),CHAR(124),"")
B37: 2.4. | C37: Проектирование ролевой модели | D37: Женя, Вася | E37: 46149 | F37: =NETWORKDAYS(E37,G37,Праздники!$A$1:$A$14) -> 12 | G37: 46167 | H37: 1 | I37: EA | J37: VD | O37: Женя выложит в удобном формате | P37: =IF(P$8=TODAY(),CHAR(124),"") | Q37: =IF(Q$8=TODAY(),CHAR(124),"") | R37: =IF(R$8=TODAY(),CHAR(124),"") | S37: =IF(S$8=TODAY(),CHAR(124),"") | T37: =IF(T$8=TODAY(),CHAR(124),"") | U37: =IF(U$8=TODAY(),CHAR(124),"") | V37: =IF(V$8=TODAY(),CHAR(124),"") | W37: =IF(W$8=TODAY(),CHAR(124),"") | ... EX37: =IF(EX$8=TODAY(),CHAR(124),"")
B38: 2.5. | C38: Интеграция между системами | D38: Женя, Вася | E38: 46154 | F38: =NETWORKDAYS(E38,G38,Праздники!$A$1:$A$14) -> 4 | G38: 46157 | H38: 1 | I38: EA, VD | P38: =IF(P$8=TODAY(),CHAR(124),"") | Q38: =IF(Q$8=TODAY(),CHAR(124),"") | R38: =IF(R$8=TODAY(),CHAR(124),"") | S38: =IF(S$8=TODAY(),CHAR(124),"") | T38: =IF(T$8=TODAY(),CHAR(124),"") | U38: =IF(U$8=TODAY(),CHAR(124),"") | V38: =IF(V$8=TODAY(),CHAR(124),"") | W38: =IF(W$8=TODAY(),CHAR(124),"") | ... EX38: =IF(EX$8=TODAY(),CHAR(124),"")
B39: 2.5.1. | C39: Загрузка данных HRPT в HC трекер | D39: Женя, Вася | E39: 46154 | F39: =NETWORKDAYS(E39,G39,Праздники!$A$1:$A$14) -> 10 | G39: 46167 | H39: 1 | I39: EA | J39: VD | M39: HC Tracker Cube | P39: =IF(P$8=TODAY(),CHAR(124),"") | Q39: =IF(Q$8=TODAY(),CHAR(124),"") | R39: =IF(R$8=TODAY(),CHAR(124),"") | S39: =IF(S$8=TODAY(),CHAR(124),"") | T39: =IF(T$8=TODAY(),CHAR(124),"") | U39: =IF(U$8=TODAY(),CHAR(124),"") | V39: =IF(V$8=TODAY(),CHAR(124),"") | W39: =IF(W$8=TODAY(),CHAR(124),"") | ... EX39: =IF(EX$8=TODAY(),CHAR(124),"")
B40: 2.5.2. | C40: Процессинг данных HCMC в HC трекер | D40: Женя, Вася, А. Коршунов | E40: 46156 | F40: =NETWORKDAYS(E40,G40,Праздники!$A$1:$A$14) -> 86 | G40: 46276 | H40: 0.9 | I40: EA, Akol | J40: VD | N40: Подготовить документ/схему | P40: =IF(P$8=TODAY(),CHAR(124),"") | Q40: =IF(Q$8=TODAY(),CHAR(124),"") | R40: =IF(R$8=TODAY(),CHAR(124),"") | S40: =IF(S$8=TODAY(),CHAR(124),"") | T40: =IF(T$8=TODAY(),CHAR(124),"") | U40: =IF(U$8=TODAY(),CHAR(124),"") | V40: =IF(V$8=TODAY(),CHAR(124),"") | W40: =IF(W$8=TODAY(),CHAR(124),"") | ... EX40: =IF(EX$8=TODAY(),CHAR(124),"")
B41: 2.5.3. | C41: Процессинг данных HC трекер в Бюджет | D41: Женя, Вася | E41: 46154 | F41: =NETWORKDAYS(E41,G41,Праздники!$A$1:$A$14) -> 88 | G41: 46276 | H41: 0.9 | I41: EA | J41: VD | N41: Подготовить документ/схему | P41: =IF(P$8=TODAY(),CHAR(124),"") | Q41: =IF(Q$8=TODAY(),CHAR(124),"") | R41: =IF(R$8=TODAY(),CHAR(124),"") | S41: =IF(S$8=TODAY(),CHAR(124),"") | T41: =IF(T$8=TODAY(),CHAR(124),"") | U41: =IF(U$8=TODAY(),CHAR(124),"") | V41: =IF(V$8=TODAY(),CHAR(124),"") | W41: =IF(W$8=TODAY(),CHAR(124),"") | ... EX41: =IF(EX$8=TODAY(),CHAR(124),"")
B42: 2.5.4. | C42: Загрузка факта из HRPT в Бюджет | D42: Женя, Вася | E42: 46156 | F42: =NETWORKDAYS(E42,G42,Праздники!$A$1:$A$14) -> 86 | G42: 46276 | H42: 0.5 | I42: EA | J42: VD | N42: Оценка целесообразности данного шага | O42: Есть ли задача сравнения номиналов с версией бюджета/прогноза? | P42: =IF(P$8=TODAY(),CHAR(124),"") | Q42: =IF(Q$8=TODAY(),CHAR(124),"") | R42: =IF(R$8=TODAY(),CHAR(124),"") | S42: =IF(S$8=TODAY(),CHAR(124),"") | T42: =IF(T$8=TODAY(),CHAR(124),"") | U42: =IF(U$8=TODAY(),CHAR(124),"") | V42: =IF(V$8=TODAY(),CHAR(124),"") | W42: =IF(W$8=TODAY(),CHAR(124),"") | ... EX42: =IF(EX$8=TODAY(),CHAR(124),"")
...

Sheet DecisionLog
A1: РЕЕСТР РЕШЕНИЙ | Значимые решения проекта
A4: ID решения | B4: Вопрос / решение | C4: Домен | D4: Владелец решения | E4: Обязательные участники | F4: Обязательное согласование | G4: Варианты / рекомендация | H4: Срок решения | I4: Статус | J4: Принятое решение | K4: Дата решения | L4: Связанные задачи / контрольные точки | M4: Эскалация | N4: Примечание

Sheet TeamRoles
B3: Роль | C3: Участник
B4: Спонсор проекта | C4: DZh
B5: Заказчик | C5: DZh
B6: Проектный менеджер | C6: AO
B7: Методолог | C7: AO
B8: Техлид | C8: VD
B9: Техписатель | C9: VD
B10: Заказчик | C10: SO
B11: UAT | C11: SO
B12: Методолог | C12: EE
B13: Заказчик | C13: EE
B14: UAT | C14: EE
... B21: Поддержка проекта | C21: EP

Sheet Праздники
A1: 46023
A2: 46024
A3: 46027
A4: 46028
A5: 46029
A6: 46030
A7: 46031
A8: 46076
A9: 46090
A10: 46143
A11: 46153
A12: 46185
... A14: 46387
